Workbook

Sheet Channel List
A1: Stage Box Input | B1: SatBox# | C1: Desk Ch# | D1: Item | E1: Mic/DI | G1: Stand | I1: Position | J1: Notes | AA1: Mic/DI Helper | AB1: Stand Helper | AC1: Item Helper | AD1: 0
A2: SB1 in01 | B2: R1 | C2: 1 | D2: Drum or instrument | AA2: =IF(E2="","",E2) | AB2: =IF(G2="","",G2) | AC2: =IF(D2="","",D2) -> Drum or instrument | AD2: =IF(AA2="","",IF(COUNTIF($AA$2:AA2,AA2)=1,MAX($AD$1:AD1)+1,""))
A3: SB1 in02 | B3: B3 | C3: 2 | D3: Vocal for vocalist | AA3: =IF(E3="","",E3) | AB3: =IF(G3="","",G3) | AC3: =IF(D3="","",D3) -> Vocal for vocalist | AD3: =IF(AA3="","",IF(COUNTIF($AA$2:AA3,AA3)=1,MAX($AD$1:AD2)+1,""))
A4: SB1 in03 | C4: 3 | AA4: =IF(E4="","",E4) | AB4: =IF(G4="","",G4) | AC4: =IF(D4="","",D4) | AD4: =IF(AA4="","",IF(COUNTIF($AA$2:AA4,AA4)=1,MAX($AD$1:AD3)+1,""))
A5: SB1 in04 | B5: y3 | C5: 4 | D5: doug | E5: sm58 | G5: tall | AA5: =IF(E5="","",E5) -> sm58 | AB5: =IF(G5="","",G5) -> tall | AC5: =IF(D5="","",D5) -> doug | AD5: =IF(AA5="","",IF(COUNTIF($AA$2:AA5,AA5)=1,MAX($AD$1:AD4)+1,"")) -> 1
A6: SB1 in05 | C6: 5 | AA6: =IF(E6="","",E6) | AB6: =IF(G6="","",G6) | AC6: =IF(D6="","",D6) | AD6: =IF(AA6="","",IF(COUNTIF($AA$2:AA6,AA6)=1,MAX($AD$1:AD5)+1,""))
A7: SB1 in06 | B7: r2 | C7: 6 | D7: test | E7: b57 | G7: round | AA7: =IF(E7="","",E7) -> b57 | AB7: =IF(G7="","",G7) -> round | AC7: =IF(D7="","",D7) -> test | AD7: =IF(AA7="","",IF(COUNTIF($AA$2:AA7,AA7)=1,MAX($AD$1:AD6)+1,"")) -> 2
A8: SB1 in07 | C8: 7 | AA8: =IF(E8="","",E8) | AB8: =IF(G8="","",G8) | AC8: =IF(D8="","",D8) | AD8: =IF(AA8="","",IF(COUNTIF($AA$2:AA8,AA8)=1,MAX($AD$1:AD7)+1,""))
A9: SB1 in08 | B9: G8 | C9: 8 | D9: Example 3 | AA9: =IF(E9="","",E9) | AB9: =IF(G9="","",G9) | AC9: =IF(D9="","",D9) -> Example 3 | AD9: =IF(AA9="","",IF(COUNTIF($AA$2:AA9,AA9)=1,MAX($AD$1:AD8)+1,""))
A10: SB1 in09 | C10: 9 | AA10: =IF(E10="","",E10) | AB10: =IF(G10="","",G10) | AC10: =IF(D10="","",D10) | AD10: =IF(AA10="","",IF(COUNTIF($AA$2:AA10,AA10)=1,MAX($AD$1:AD9)+1,""))
A11: SB1 in10 | B11: Y9 | C11: 10 | D11: Example 4 | AA11: =IF(E11="","",E11) | AB11: =IF(G11="","",G11) | AC11: =IF(D11="","",D11) -> Example 4 | AD11: =IF(AA11="","",IF(COUNTIF($AA$2:AA11,AA11)=1,MAX($AD$1:AD10)+1,""))
A12: SB1 in11 | C12: 11 | AA12: =IF(E12="","",E12) | AB12: =IF(G12="","",G12) | AC12: =IF(D12="","",D12) | AD12: =IF(AA12="","",IF(COUNTIF($AA$2:AA12,AA12)=1,MAX($AD$1:AD11)+1,""))
A13: SB1 in12 | C13: 12 | AA13: =IF(E13="","",E13) | AB13: =IF(G13="","",G13) | AC13: =IF(D13="","",D13) | AD13: =IF(AA13="","",IF(COUNTIF($AA$2:AA13,AA13)=1,MAX($AD$1:AD12)+1,""))
A14: SB1 in13 | C14: 13 | AA14: =IF(E14="","",E14) | AB14: =IF(G14="","",G14) | AC14: =IF(D14="","",D14) | AD14: =IF(AA14="","",IF(COUNTIF($AA$2:AA14,AA14)=1,MAX($AD$1:AD13)+1,""))
A15: SB1 in14 | C15: 14 | AA15: =IF(E15="","",E15) | AB15: =IF(G15="","",G15) | AC15: =IF(D15="","",D15) | AD15: =IF(AA15="","",IF(COUNTIF($AA$2:AA15,AA15)=1,MAX($AD$1:AD14)+1,""))
A16: SB1 in15 | B16: O4 | C16: 15 | D16: Example 5 | AA16: =IF(E16="","",E16) | AB16: =IF(G16="","",G16) | AC16: =IF(D16="","",D16) -> Example 5 | AD16: =IF(AA16="","",IF(COUNTIF($AA$2:AA16,AA16)=1,MAX($AD$1:AD15)+1,""))
A17: SB1 in16 | B17: P11 | C17: 16 | D17: Example 6 | AA17: =IF(E17="","",E17) | AB17: =IF(G17="","",G17) | AC17: =IF(D17="","",D17) -> Example 6 | AD17: =IF(AA17="","",IF(COUNTIF($AA$2:AA17,AA17)=1,MAX($AD$1:AD16)+1,""))
A18: SB1 in17 | C18: 17 | AA18: =IF(E18="","",E18) | AB18: =IF(G18="","",G18) | AC18: =IF(D18="","",D18) | AD18: =IF(AA18="","",IF(COUNTIF($AA$2:AA18,AA18)=1,MAX($AD$1:AD17)+1,""))
A19: SB1 in18 | C19: 18 | AA19: =IF(E19="","",E19) | AB19: =IF(G19="","",G19) | AC19: =IF(D19="","",D19) | AD19: =IF(AA19="","",IF(COUNTIF($AA$2:AA19,AA19)=1,MAX($AD$1:AD18)+1,""))
A20: SB1 in19 | C20: 19 | AA20: =IF(E20="","",E20) | AB20: =IF(G20="","",G20) | AC20: =IF(D20="","",D20) | AD20: =IF(AA20="","",IF(COUNTIF($AA$2:AA20,AA20)=1,MAX($AD$1:AD19)+1,""))
A21: SB1 in20 | C21: 20 | AA21: =IF(E21="","",E21) | AB21: =IF(G21="","",G21) | AC21: =IF(D21="","",D21) | AD21: =IF(AA21="","",IF(COUNTIF($AA$2:AA21,AA21)=1,MAX($AD$1:AD20)+1,""))
A22: SB1 in21 | C22: 21 | AA22: =IF(E22="","",E22) | AB22: =IF(G22="","",G22) | AC22: =IF(D22="","",D22) | AD22: =IF(AA22="","",IF(COUNTIF($AA$2:AA22,AA22)=1,MAX($AD$1:AD21)+1,""))
A23: SB1 in22 | C23: 22 | AA23: =IF(E23="","",E23) | AB23: =IF(G23="","",G23) | AC23: =IF(D23="","",D23) | AD23: =IF(AA23="","",IF(COUNTIF($AA$2:AA23,AA23)=1,MAX($AD$1:AD22)+1,""))
A24: SB1 in23 | C24: 23 | AA24: =IF(E24="","",E24) | AB24: =IF(G24="","",G24) | AC24: =IF(D24="","",D24) | AD24: =IF(AA24="","",IF(COUNTIF($AA$2:AA24,AA24)=1,MAX($AD$1:AD23)+1,""))
A25: SB1 in24 | C25: 24 | AA25: =IF(E25="","",E25) | AB25: =IF(G25="","",G25) | AC25: =IF(D25="","",D25) | AD25: =IF(AA25="","",IF(COUNTIF($AA$2:AA25,AA25)=1,MAX($AD$1:AD24)+1,""))
A26: SB1 in25 | C26: 25 | AA26: =IF(E26="","",E26) | AB26: =IF(G26="","",G26) | AC26: =IF(D26="","",D26) | AD26: =IF(AA26="","",IF(COUNTIF($AA$2:AA26,AA26)=1,MAX($AD$1:AD25)+1,""))
A27: SB1 in26 | C27: 26 | AA27: =IF(E27="","",E27) | AB27: =IF(G27="","",G27) | AC27: =IF(D27="","",D27) | AD27: =IF(AA27="","",IF(COUNTIF($AA$2:AA27,AA27)=1,MAX($AD$1:AD26)+1,""))
A28: SB1 in27 | C28: 27 | AA28: =IF(E28="","",E28) | AB28: =IF(G28="","",G28) | AC28: =IF(D28="","",D28) | AD28: =IF(AA28="","",IF(COUNTIF($AA$2:AA28,AA28)=1,MAX($AD$1:AD27)+1,""))
A29: SB1 in28 | C29: 28 | AA29: =IF(E29="","",E29) | AB29: =IF(G29="","",G29) | AC29: =IF(D29="","",D29) | AD29: =IF(AA29="","",IF(COUNTIF($AA$2:AA29,AA29)=1,MAX($AD$1:AD28)+1,""))
... A49: SB1 in48 | C49: 48 | AA49: =IF(E49="","",E49) | AB49: =IF(G49="","",G49) | AC49: =IF(D49="","",D49) | AD49: =IF(AA49="","",IF(COUNTIF($AA$2:AA49,AA49)=1,MAX($AD$1:AD48)+1,""))
C50: 49 | AA50: =IF(E50="","",E50) | AB50: =IF(G50="","",G50) | AC50: =IF(D50="","",D50) | AD50: =IF(AA50="","",IF(COUNTIF($AA$2:AA50,AA50)=1,MAX($AD$1:AD49)+1,""))
C51: 50 | AA51: =IF(E51="","",E51) | AB51: =IF(G51="","",G51) | AC51: =IF(D51="","",D51) | AD51: =IF(AA51="","",IF(COUNTIF($AA$2:AA51,AA51)=1,MAX($AD$1:AD50)+1,""))
C52: 51 | AA52: =IF(E52="","",E52) | AB52: =IF(G52="","",G52) | AC52: =IF(D52="","",D52) | AD52: =IF(AA52="","",IF(COUNTIF($AA$2:AA52,AA52)=1,MAX($AD$1:AD51)+1,""))
C53: 52 | AA53: =IF(E53="","",E53) | AB53: =IF(G53="","",G53) | AC53: =IF(D53="","",D53) | AD53: =IF(AA53="","",IF(COUNTIF($AA$2:AA53,AA53)=1,MAX($AD$1:AD52)+1,""))
C54: 53 | AA54: =IF(E54="","",E54) | AB54: =IF(G54="","",G54) | AC54: =IF(D54="","",D54) | AD54: =IF(AA54="","",IF(COUNTIF($AA$2:AA54,AA54)=1,MAX($AD$1:AD53)+1,""))
C55: 54 | AA55: =IF(E55="","",E55) | AB55: =IF(G55="","",G55) | AC55: =IF(D55="","",D55) | AD55: =IF(AA55="","",IF(COUNTIF($AA$2:AA55,AA55)=1,MAX($AD$1:AD54)+1,""))
C56: 55 | AA56: =IF(E56="","",E56) | AB56: =IF(G56="","",G56) | AC56: =IF(D56="","",D56) | AD56: =IF(AA56="","",IF(COUNTIF($AA$2:AA56,AA56)=1,MAX($AD$1:AD55)+1,""))
C57: 56 | AA57: =IF(E57="","",E57) | AB57: =IF(G57="","",G57) | AC57: =IF(D57="","",D57) | AD57: =IF(AA57="","",IF(COUNTIF($AA$2:AA57,AA57)=1,MAX($AD$1:AD56)+1,""))
C58: 57 | AA58: =IF(E58="","",E58) | AB58: =IF(G58="","",G58) | AC58: =IF(D58="","",D58) | AD58: =IF(AA58="","",IF(COUNTIF($AA$2:AA58,AA58)=1,MAX($AD$1:AD57)+1,""))
C59: 58 | AA59: =IF(E59="","",E59) | AB59: =IF(G59="","",G59) | AC59: =IF(D59="","",D59) | AD59: =IF(AA59="","",IF(COUNTIF($AA$2:AA59,AA59)=1,MAX($AD$1:AD58)+1,""))
...

Sheet Mic & DI List
A1: Mic Pick List | D1: Stand Total Count
A2: (AUTO Filled from Channel list) | B2: Full Mic List | D2: Tall Stands | E2: =COUNTIF('Channel List'!$G$2:$G$101,"Tall*")+'Channel List'!$C$99 -> 1
A3: Mic | B3: Quantity | D3: Short Stands | E3: =COUNTIF('Channel List'!$G$2:$G$101,"Short*")+'Channel List'!$C$100 -> 0
A4: =IF(COUNTIF('Channel List'!$AD$2:$AD$101,ROW(A1))=0,"",INDEX('Channel List'!$AA$2:$AA$101,MATCH(ROW(A1),'Channel List'!$AD$2:$AD$101,0))) -> sm58 | B4: =IF(A4="","",COUNTIF('Channel List'!$AA$2:$AA$101,A4)) -> 1 | D4: Round Bases | E4: =COUNTIF('Channel List'!$G$2:$G$101,"Round*")+'Channel List'!$C$101 -> 1
A5: =IF(COUNTIF('Channel List'!$AD$2:$AD$101,ROW(A2))=0,"",INDEX('Channel List'!$AA$2:$AA$101,MATCH(ROW(A2),'Channel List'!$AD$2:$AD$101,0))) -> b57 | B5: =IF(A5="","",COUNTIF('Channel List'!$AA$2:$AA$101,A5)) -> 1
A6: =IF(COUNTIF('Channel List'!$AD$2:$AD$101,ROW(A3))=0,"",INDEX('Channel List'!$AA$2:$AA$101,MATCH(ROW(A3),'Channel List'!$AD$2:$AD$101,0))) | B6: =IF(A6="","",COUNTIF('Channel List'!$AA$2:$AA$101,A6))
A7: =IF(COUNTIF('Channel List'!$AD$2:$AD$101,ROW(A4))=0,"",INDEX('Channel List'!$AA$2:$AA$101,MATCH(ROW(A4),'Channel List'!$AD$2:$AD$101,0))) | B7: =IF(A7="","",COUNTIF('Channel List'!$AA$2:$AA$101,A7))
A8: =IF(COUNTIF('Channel List'!$AD$2:$AD$101,ROW(A5))=0,"",INDEX('Channel List'!$AA$2:$AA$101,MATCH(ROW(A5),'Channel List'!$AD$2:$AD$101,0))) | B8: =IF(A8="","",COUNTIF('Channel List'!$AA$2:$AA$101,A8))
A9: =IF(COUNTIF('Channel List'!$AD$2:$AD$101,ROW(A6))=0,"",INDEX('Channel List'!$AA$2:$AA$101,MATCH(ROW(A6),'Channel List'!$AD$2:$AD$101,0))) | B9: =IF(A9="","",COUNTIF('Channel List'!$AA$2:$AA$101,A9))
A10: =IF(COUNTIF('Channel List'!$AD$2:$AD$101,ROW(A7))=0,"",INDEX('Channel List'!$AA$2:$AA$101,MATCH(ROW(A7),'Channel List'!$AD$2:$AD$101,0))) | B10: =IF(A10="","",COUNTIF('Channel List'!$AA$2:$AA$101,A10))
A11: =IF(COUNTIF('Channel List'!$AD$2:$AD$101,ROW(A8))=0,"",INDEX('Channel List'!$AA$2:$AA$101,MATCH(ROW(A8),'Channel List'!$AD$2:$AD$101,0))) | B11: =IF(A11="","",COUNTIF('Channel List'!$AA$2:$AA$101,A11))
A12: =IF(COUNTIF('Channel List'!$AD$2:$AD$101,ROW(A9))=0,"",INDEX('Channel List'!$AA$2:$AA$101,MATCH(ROW(A9),'Channel List'!$AD$2:$AD$101,0))) | B12: =IF(A12="","",COUNTIF('Channel List'!$AA$2:$AA$101,A12))
A13: =IF(COUNTIF('Channel List'!$AD$2:$AD$101,ROW(A10))=0,"",INDEX('Channel List'!$AA$2:$AA$101,MATCH(ROW(A10),'Channel List'!$AD$2:$AD$101,0))) | B13: =IF(A13="","",COUNTIF('Channel List'!$AA$2:$AA$101,A13))
A14: =IF(COUNTIF('Channel List'!$AD$2:$AD$101,ROW(A11))=0,"",INDEX('Channel List'!$AA$2:$AA$101,MATCH(ROW(A11),'Channel List'!$AD$2:$AD$101,0))) | B14: =IF(A14="","",COUNTIF('Channel List'!$AA$2:$AA$101,A14))
A15: =IF(COUNTIF('Channel List'!$AD$2:$AD$101,ROW(A12))=0,"",INDEX('Channel List'!$AA$2:$AA$101,MATCH(ROW(A12),'Channel List'!$AD$2:$AD$101,0))) | B15: =IF(A15="","",COUNTIF('Channel List'!$AA$2:$AA$101,A15))
A16: =IF(COUNTIF('Channel List'!$AD$2:$AD$101,ROW(A13))=0,"",INDEX('Channel List'!$AA$2:$AA$101,MATCH(ROW(A13),'Channel List'!$AD$2:$AD$101,0))) | B16: =IF(A16="","",COUNTIF('Channel List'!$AA$2:$AA$101,A16))
... A39: =IF(COUNTIF('Channel List'!$AD$2:$AD$101,ROW(A36))=0,"",INDEX('Channel List'!$AA$2:$AA$101,MATCH(ROW(A36),'Channel List'!$AD$2:$AD$101,0))) | B39: =IF(A39="","",COUNTIF('Channel List'!$AA$2:$AA$101,A39))
A40: Total | B40: =SUM(B4:B39) -> 2

Sheet SatBox Lables
A1: SatBox Labels
A2: Auto-populated from Channel List
A4: Red (1) | B4: Lable | D4: Green (2) | E4: Lable
A5: R1 | B5: =IF(COUNTIF('Channel List'!$B$2:$B$101,A5)=0,"",INDEX('Channel List'!$AC$2:$AC$101,MATCH(A5,'Channel List'!$B$2:$B$101,0))) -> Drum or instrument | D5: G1 | E5: =IF(COUNTIF('Channel List'!$B$2:$B$101,D5)=0,"",INDEX('Channel List'!$AC$2:$AC$101,MATCH(D5,'Channel List'!$B$2:$B$101,0)))
A6: R2 | B6: =IF(COUNTIF('Channel List'!$B$2:$B$101,A6)=0,"",INDEX('Channel List'!$AC$2:$AC$101,MATCH(A6,'Channel List'!$B$2:$B$101,0))) -> test | D6: G2 | E6: =IF(COUNTIF('Channel List'!$B$2:$B$101,D6)=0,"",INDEX('Channel List'!$AC$2:$AC$101,MATCH(D6,'Channel List'!$B$2:$B$101,0)))
A7: R3 | B7: =IF(COUNTIF('Channel List'!$B$2:$B$101,A7)=0,"",INDEX('Channel List'!$AC$2:$AC$101,MATCH(A7,'Channel List'!$B$2:$B$101,0))) | D7: G3 | E7: =IF(COUNTIF('Channel List'!$B$2:$B$101,D7)=0,"",INDEX('Channel List'!$AC$2:$AC$101,MATCH(D7,'Channel List'!$B$2:$B$101,0)))
A8: R4 | B8: =IF(COUNTIF('Channel List'!$B$2:$B$101,A8)=0,"",INDEX('Channel List'!$AC$2:$AC$101,MATCH(A8,'Channel List'!$B$2:$B$101,0))) | D8: G4 | E8: =IF(COUNTIF('Channel List'!$B$2:$B$101,D8)=0,"",INDEX('Channel List'!$AC$2:$AC$101,MATCH(D8,'Channel List'!$B$2:$B$101,0)))
A9: R5 | B9: =IF(COUNTIF('Channel List'!$B$2:$B$101,A9)=0,"",INDEX('Channel List'!$AC$2:$AC$101,MATCH(A9,'Channel List'!$B$2:$B$101,0))) | D9: G5 | E9: =IF(COUNTIF('Channel List'!$B$2:$B$101,D9)=0,"",INDEX('Channel List'!$AC$2:$AC$101,MATCH(D9,'Channel List'!$B$2:$B$101,0)))
A10: R6 | B10: =IF(COUNTIF('Channel List'!$B$2:$B$101,A10)=0,"",INDEX('Channel List'!$AC$2:$AC$101,MATCH(A10,'Channel List'!$B$2:$B$101,0))) | D10: G6 | E10: =IF(COUNTIF('Channel List'!$B$2:$B$101,D10)=0,"",INDEX('Channel List'!$AC$2:$AC$101,MATCH(D10,'Channel List'!$B$2:$B$101,0)))
A11: R7 | B11: =IF(COUNTIF('Channel List'!$B$2:$B$101,A11)=0,"",INDEX('Channel List'!$AC$2:$AC$101,MATCH(A11,'Channel List'!$B$2:$B$101,0))) | D11: G7 | E11: =IF(COUNTIF('Channel List'!$B$2:$B$101,D11)=0,"",INDEX('Channel List'!$AC$2:$AC$101,MATCH(D11,'Channel List'!$B$2:$B$101,0)))
A12: R8 | B12: =IF(COUNTIF('Channel List'!$B$2:$B$101,A12)=0,"",INDEX('Channel List'!$AC$2:$AC$101,MATCH(A12,'Channel List'!$B$2:$B$101,0))) | D12: G8 | E12: =IF(COUNTIF('Channel List'!$B$2:$B$101,D12)=0,"",INDEX('Channel List'!$AC$2:$AC$101,MATCH(D12,'Channel List'!$B$2:$B$101,0))) -> Example 3
A13: R9 | B13: =IF(COUNTIF('Channel List'!$B$2:$B$101,A13)=0,"",INDEX('Channel List'!$AC$2:$AC$101,MATCH(A13,'Channel List'!$B$2:$B$101,0))) | D13: G9 | E13: =IF(COUNTIF('Channel List'!$B$2:$B$101,D13)=0,"",INDEX('Channel List'!$AC$2:$AC$101,MATCH(D13,'Channel List'!$B$2:$B$101,0)))
A14: R10 | B14: =IF(COUNTIF('Channel List'!$B$2:$B$101,A14)=0,"",INDEX('Channel List'!$AC$2:$AC$101,MATCH(A14,'Channel List'!$B$2:$B$101,0))) | D14: G10 | E14: =IF(COUNTIF('Channel List'!$B$2:$B$101,D14)=0,"",INDEX('Channel List'!$AC$2:$AC$101,MATCH(D14,'Channel List'!$B$2:$B$101,0)))
A15: R11 | B15: =IF(COUNTIF('Channel List'!$B$2:$B$101,A15)=0,"",INDEX('Channel List'!$AC$2:$AC$101,MATCH(A15,'Channel List'!$B$2:$B$101,0))) | D15: G11 | E15: =IF(COUNTIF('Channel List'!$B$2:$B$101,D15)=0,"",INDEX('Channel List'!$AC$2:$AC$101,MATCH(D15,'Channel List'!$B$2:$B$101,0)))
A16: R12 | B16: =IF(COUNTIF('Channel List'!$B$2:$B$101,A16)=0,"",INDEX('Channel List'!$AC$2:$AC$101,MATCH(A16,'Channel List'!$B$2:$B$101,0))) | D16: G12 | E16: =IF(COUNTIF('Channel List'!$B$2:$B$101,D16)=0,"",INDEX('Channel List'!$AC$2:$AC$101,MATCH(D16,'Channel List'!$B$2:$B$101,0)))
B17: =IF(COUNTIF('Channel List'!$B$2:$B$101,A17)=0,"",VLOOKUP(A17,'Channel List'!$B$2:$L$101,11,FALSE())) | E17: =IF(COUNTIF('Channel List'!$B$2:$B$101,D17)=0,"",VLOOKUP(D17,'Channel List'!$B$2:$L$101,11,FALSE()))
B18: =IF(COUNTIF('Channel List'!$B$2:$B$101,A18)=0,"",VLOOKUP(A18,'Channel List'!$B$2:$L$101,11,FALSE())) | E18: =IF(COUNTIF('Channel List'!$B$2:$B$101,D18)=0,"",VLOOKUP(D18,'Channel List'!$B$2:$L$101,11,FALSE()))
A19: Blue (3) | B19: =IF(COUNTIF('Channel List'!$B$2:$B$101,A19)=0,"",VLOOKUP(A19,'Channel List'!$B$2:$L$101,11,FALSE())) | D19: Yellow (4) | E19: =IF(COUNTIF('Channel List'!$B$2:$B$101,D19)=0,"",VLOOKUP(D19,'Channel List'!$B$2:$L$101,11,FALSE()))
A20: B1 | B20: =IF(COUNTIF('Channel List'!$B$2:$B$101,A20)=0,"",INDEX('Channel List'!$AC$2:$AC$101,MATCH(A20,'Channel List'!$B$2:$B$101,0))) | D20: Y1 | E20: =IF(COUNTIF('Channel List'!$B$2:$B$101,D20)=0,"",INDEX('Channel List'!$AC$2:$AC$101,MATCH(D20,'Channel List'!$B$2:$B$101,0)))
A21: B2 | B21: =IF(COUNTIF('Channel List'!$B$2:$B$101,A21)=0,"",INDEX('Channel List'!$AC$2:$AC$101,MATCH(A21,'Channel List'!$B$2:$B$101,0))) | D21: Y2 | E21: =IF(COUNTIF('Channel List'!$B$2:$B$101,D21)=0,"",INDEX('Channel List'!$AC$2:$AC$101,MATCH(D21,'Channel List'!$B$2:$B$101,0)))
A22: B3 | B22: =IF(COUNTIF('Channel List'!$B$2:$B$101,A22)=0,"",INDEX('Channel List'!$AC$2:$AC$101,MATCH(A22,'Channel List'!$B$2:$B$101,0))) -> Vocal for vocalist | D22: Y3 | E22: =IF(COUNTIF('Channel List'!$B$2:$B$101,D22)=0,"",INDEX('Channel List'!$AC$2:$AC$101,MATCH(D22,'Channel List'!$B$2:$B$101,0))) -> doug
A23: B4 | B23: =IF(COUNTIF('Channel List'!$B$2:$B$101,A23)=0,"",INDEX('Channel List'!$AC$2:$AC$101,MATCH(A23,'Channel List'!$B$2:$B$101,0))) | D23: Y4 | E23: =IF(COUNTIF('Channel List'!$B$2:$B$101,D23)=0,"",INDEX('Channel List'!$AC$2:$AC$101,MATCH(D23,'Channel List'!$B$2:$B$101,0)))
A24: B5 | B24: =IF(COUNTIF('Channel List'!$B$2:$B$101,A24)=0,"",INDEX('Channel List'!$AC$2:$AC$101,MATCH(A24,'Channel List'!$B$2:$B$101,0))) | D24: Y5 | E24: =IF(COUNTIF('Channel List'!$B$2:$B$101,D24)=0,"",INDEX('Channel List'!$AC$2:$AC$101,MATCH(D24,'Channel List'!$B$2:$B$101,0)))
A25: B6 | B25: =IF(COUNTIF('Channel List'!$B$2:$B$101,A25)=0,"",INDEX('Channel List'!$AC$2:$AC$101,MATCH(A25,'Channel List'!$B$2:$B$101,0))) | D25: Y6 | E25: =IF(COUNTIF('Channel List'!$B$2:$B$101,D25)=0,"",INDEX('Channel List'!$AC$2:$AC$101,MATCH(D25,'Channel List'!$B$2:$B$101,0)))
A26: B7 | B26: =IF(COUNTIF('Channel List'!$B$2:$B$101,A26)=0,"",INDEX('Channel List'!$AC$2:$AC$101,MATCH(A26,'Channel List'!$B$2:$B$101,0))) | D26: Y7 | E26: =IF(COUNTIF('Channel List'!$B$2:$B$101,D26)=0,"",INDEX('Channel List'!$AC$2:$AC$101,MATCH(D26,'Channel List'!$B$2:$B$101,0)))
A27: B8 | B27: =IF(COUNTIF('Channel List'!$B$2:$B$101,A27)=0,"",INDEX('Channel List'!$AC$2:$AC$101,MATCH(A27,'Channel List'!$B$2:$B$101,0))) | D27: Y8 | E27: =IF(COUNTIF('Channel List'!$B$2:$B$101,D27)=0,"",INDEX('Channel List'!$AC$2:$AC$101,MATCH(D27,'Channel List'!$B$2:$B$101,0)))
A28: B9 | B28: =IF(COUNTIF('Channel List'!$B$2:$B$101,A28)=0,"",INDEX('Channel List'!$AC$2:$AC$101,MATCH(A28,'Channel List'!$B$2:$B$101,0))) | D28: Y9 | E28: =IF(COUNTIF('Channel List'!$B$2:$B$101,D28)=0,"",INDEX('Channel List'!$AC$2:$AC$101,MATCH(D28,'Channel List'!$B$2:$B$101,0))) -> Example 4
A29: B10 | B29: =IF(COUNTIF('Channel List'!$B$2:$B$101,A29)=0,"",INDEX('Channel List'!$AC$2:$AC$101,MATCH(A29,'Channel List'!$B$2:$B$101,0))) | D29: Y10 | E29: =IF(COUNTIF('Channel List'!$B$2:$B$101,D29)=0,"",INDEX('Channel List'!$AC$2:$AC$101,MATCH(D29,'Channel List'!$B$2:$B$101,0)))
A30: B11 | B30: =IF(COUNTIF('Channel List'!$B$2:$B$101,A30)=0,"",INDEX('Channel List'!$AC$2:$AC$101,MATCH(A30,'Channel List'!$B$2:$B$101,0))) | D30: Y11 | E30: =IF(COUNTIF('Channel List'!$B$2:$B$101,D30)=0,"",INDEX('Channel List'!$AC$2:$AC$101,MATCH(D30,'Channel List'!$B$2:$B$101,0)))
A31: B12 | B31: =IF(COUNTIF('Channel List'!$B$2:$B$101,A31)=0,"",INDEX('Channel List'!$AC$2:$AC$101,MATCH(A31,'Channel List'!$B$2:$B$101,0))) | D31: Y12 | E31: =IF(COUNTIF('Channel List'!$B$2:$B$101,D31)=0,"",INDEX('Channel List'!$AC$2:$AC$101,MATCH(D31,'Channel List'!$B$2:$B$101,0)))
B32: =IF(COUNTIF('Channel List'!$B$2:$B$101,A32)=0,"",VLOOKUP(A32,'Channel List'!$B$2:$L$101,11,FALSE())) | E32: =IF(COUNTIF('Channel List'!$B$2:$B$101,D32)=0,"",VLOOKUP(D32,'Channel List'!$B$2:$L$101,11,FALSE()))
B33: =IF(COUNTIF('Channel List'!$B$2:$B$101,A33)=0,"",VLOOKUP(A33,'Channel List'!$B$2:$L$101,11,FALSE())) | E33: =IF(COUNTIF('Channel List'!$B$2:$B$101,D33)=0,"",VLOOKUP(D33,'Channel List'!$B$2:$L$101,11,FALSE()))
A34: Orange (5) | B34: =IF(COUNTIF('Channel List'!$B$2:$B$101,A34)=0,"",VLOOKUP(A34,'Channel List'!$B$2:$L$101,11,FALSE())) | D34: Purple (6) | E34: =IF(COUNTIF('Channel List'!$B$2:$B$101,D34)=0,"",VLOOKUP(D34,'Channel List'!$B$2:$L$101,11,FALSE()))
A35: O1 | B35: =IF(COUNTIF('Channel List'!$B$2:$B$101,A35)=0,"",INDEX('Channel List'!$AC$2:$AC$101,MATCH(A35,'Channel List'!$B$2:$B$101,0))) | D35: P1 | E35: =IF(COUNTIF('Channel List'!$B$2:$B$101,D35)=0,"",INDEX('Channel List'!$AC$2:$AC$101,MATCH(D35,'Channel List'!$B$2:$B$101,0)))
A36: O2 | B36: =IF(COUNTIF('Channel List'!$B$2:$B$101,A36)=0,"",INDEX('Channel List'!$AC$2:$AC$101,MATCH(A36,'Channel List'!$B$2:$B$101,0))) | D36: P2 | E36: =IF(COUNTIF('Channel List'!$B$2:$B$101,D36)=0,"",INDEX('Channel List'!$AC$2:$AC$101,MATCH(D36,'Channel List'!$B$2:$B$101,0)))
A37: O3 | B37: =IF(COUNTIF('Channel List'!$B$2:$B$101,A37)=0,"",INDEX('Channel List'!$AC$2:$AC$101,MATCH(A37,'Channel List'!$B$2:$B$101,0))) | D37: P3 | E37: =IF(COUNTIF('Channel List'!$B$2:$B$101,D37)=0,"",INDEX('Channel List'!$AC$2:$AC$101,MATCH(D37,'Channel List'!$B$2:$B$101,0)))
A38: O4 | B38: =IF(COUNTIF('Channel List'!$B$2:$B$101,A38)=0,"",INDEX('Channel List'!$AC$2:$AC$101,MATCH(A38,'Channel List'!$B$2:$B$101,0))) -> Example 5 | D38: P4 | E38: =IF(COUNTIF('Channel List'!$B$2:$B$101,D38)=0,"",INDEX('Channel List'!$AC$2:$AC$101,MATCH(D38,'Channel List'!$B$2:$B$101,0)))
A39: O5 | B39: =IF(COUNTIF('Channel List'!$B$2:$B$101,A39)=0,"",INDEX('Channel List'!$AC$2:$AC$101,MATCH(A39,'Channel List'!$B$2:$B$101,0))) | D39: P5 | E39: =IF(COUNTIF('Channel List'!$B$2:$B$101,D39)=0,"",INDEX('Channel List'!$AC$2:$AC$101,MATCH(D39,'Channel List'!$B$2:$B$101,0)))
A40: O6 | B40: =IF(COUNTIF('Channel List'!$B$2:$B$101,A40)=0,"",INDEX('Channel List'!$AC$2:$AC$101,MATCH(A40,'Channel List'!$B$2:$B$101,0))) | D40: P6 | E40: =IF(COUNTIF('Channel List'!$B$2:$B$101,D40)=0,"",INDEX('Channel List'!$AC$2:$AC$101,MATCH(D40,'Channel List'!$B$2:$B$101,0)))
A41: O7 | B41: =IF(COUNTIF('Channel List'!$B$2:$B$101,A41)=0,"",INDEX('Channel List'!$AC$2:$AC$101,MATCH(A41,'Channel List'!$B$2:$B$101,0))) | D41: P7 | E41: =IF(COUNTIF('Channel List'!$B$2:$B$101,D41)=0,"",INDEX('Channel List'!$AC$2:$AC$101,MATCH(D41,'Channel List'!$B$2:$B$101,0)))
...

Sheet Equipment Pick List
A1: ='Channel List'!#REF!&" - Equipment Pick List" -> #REF!
A2: Use this sheet as the final pack checklist and add quantities manually as needed
A3: Type | B3: Item | C3: Quantity | D3: Pack Where? | E3: Notes
A8: examples….
A9: Case | B9: Tour Draws Case | C9: 1 | D9: Tour Draws Case
A10: Mics | B10: As per Mic Pick List | C10: Lots | D10: Tour Draws Case: Draws 1-4
